错误处理在我们自己搭建的 Node.js 服务中，产生错误是很常见的。开发环境下我们可以通过在对应位置添加断点的方式调试，也可以在 console.log 中打印出关键信息以定位问题但是生产环境中的错误处理和调试就会比较麻烦：

首先，对服务高稳定性的需求导致我们不能把服务器中的代码打上断点慢慢调试，这样服务器的相应会被阻塞。其次，在不确定错误产生的地点时，一点点增加 console.log 的深度然后不断重启服务显然不限时再者，使用我们服务的用户应该尽快地知道有错误发生，并且收到相应的解决方案这就对服务器的错误处理和记录提出了一些要求

1. 错误必须在合适的地方被抛出，便于我们快速定位是哪一行代码出了问题
2. 产生错误时，必须要做一些及时的处理，保证服务器能够对这次请求产生合适的相应

### Node.js 中的错误（异常）创建一个错误对象

    new Error('oops')

或者使用 V8 提供的接口

    const obj = {message:'oops'} // 可以手动指定 message 和 name 属性
    Error.captureStackTrace(obj)

抛出一个错误

    throw Error('oops')

在同步代码中捕获一个错误

    try {
      throw Error('error in try-catch')
    } catch(e) {
      console.log(e.message);
      throw e;
    }

在 async/await 代码中捕获一个错误

```js
async function bar() {
  throw new Error('error in bar')
}

;(async () => {
  await bar()
})()
  .then(r => {})
  .catch(e => {
    console.log(e)
  })
// 或者
async function bar() {
  throw new Error('error in bar')
}
;(async () => {
  try {
    await bar()
  } catch (e) {
    console.log(e)
  }
})()
  .then(r => {})
  .catch(e => {})
```

但是如果试图在 async 函数外用 try/catch

```js
async function bar() {
  throw new Error('error in bar')
}

try {
  ;(async () => {
    await bar()
  })()
} catch (e) {
  console.log(e)
}
```

你会收获一份 unhandledRejection，在 Node.js 风格回调中，错误处理应该是这个画风

```js
function foo(cb) {
  cb(new Error('error in callback'))
}
foo(e => {
  console.log(e)
})
```

---

error.stack



### 关于 unhandledRejection 和 uncaughtException

如果在 promise 中抛出了一个异常，却没有被.catch 拦截，就会出现 unhandledRejection
如果出现了一个 exception，却没有被 try/catch 包裹住，则会出现 uncaughtException

    new Promise((rl,rj)=>{
      throw new Error('will cause unhandled rejection')
    })

我们需要这样处理

    process.on('unhandledRejection', (p,reason) => { })

如果是 uncaughtException，则应该

    process.on('uncaughtException', (e)=>{
      console.log(e);  // undefined.name
    })

### HTTP 请求的异常处理和自定义错误码

如果在一次 HTTP 请求中，有错误被产生，应该立即返回这次请求，并附上相应的错误码和提示信息我们使用拓展过的 Error 类来实现这个效果定义一个 Error 对象

```js
class HTTPBaseError extends Error {
  constructor(httpStatusCode, httpMsg, errCode, msg) {
    super(`HTTP ERROR: ${msg}`)
    this.httpStatusCode = httpStatusCode
    this.httpMsg = httpMsg
    this.errCode = errCode
  }
}
throw new HTTPBaseError(500, '出错啦', 100001, 'internal_server_error')
```

日志处理在关于错误处理的部分中我们提到了，应该在正确的的位置将错误对应的内容打印下来然而在 Node.js 中，如果我们直接使用 console.log 来打印错误，是不太好的。

首先，如果不重定向 console.log 到文件，那么日志并没有被持久化，这肯定是不行滴其次，Node.js 的 console.log 的输出，会根据输出的目的对象，有可能进行同步输出，会阻塞进程我们将会使用 winston 来进行日志处理

